ceback (most recent call last):
  File "vk.py", line 5, in <module>
    z=urllib2.urlopen(id).read()
  File "/usr/lib/python2.7/urllib2.py", line 126, in urlopen
    return _opener.open(url, data, timeout)
  File "/usr/lib/python2.7/urllib2.py", line 400, in open
    response = meth(req, response)
  File "/usr/lib/python2.7/urllib2.py", line 513, in http_response
    'http', request, response, code, msg, hdrs)
  File "/usr/lib/python2.7/urllib2.py", line 432, in error
    result = self._call_chain(*args)
  File "/usr/lib/python2.7/urllib2.py", line 372, in _call_chain
    result = func(*args)
  File "/usr/lib/python2.7/urllib2.py", line 619, in http_error_302
    return self.parent.open(new, timeout=req.timeout)
  File "/usr/lib/python2.7/urllib2.py", line 400, in open
    response = meth(req, response)
  File "/usr/lib/python2.7/urllib2.py", line 513, in http_response
    'http', request, response, code, msg, hdrs)
  File "/usr/lib/python2.7/urllib2.py", line 432, in error
    result = self._call_chain(*args)
  File "/usr/lib/python2.7/urllib2.py", line 372, in _call_chain
    result = func(*args)
  File "/usr/lib/python2.7/urllib2.py", line 619, in http_error_302
    return self.parent.open(new, timeout=req.timeout)
  File "/usr/lib/python2.7/urllib2.py", line 400, in open
    response = meth(req, response)
  File "/usr/lib/python2.7/urllib2.py", line 513, in http_response
    'http', request, response, code, msg, hdrs)
  File "/usr/lib/python2.7/urllib2.py", line 438, in error
    return self._call_chain(*args)
  File "/usr/lib/python2.7/urllib2.py", line 372, in _call_chain
    result = func(*args)
  File "/usr/lib/python2.7/urllib2.py", line 521, in http_error_default
    raise HTTPError(req.get_full_url(), code, msg, hdrs, fp)
urllib2.HTTPError: HTTP Error 404: Not Found
costansin@Comp:~/Рабочий стол/vk$ 

